Workbook

Sheet Roadmap
A1: Core Java Roadmap — mapped to 5 YouTube playlists
A2: Amber rows = ★ Critical (interview-heavy). Pale yellow = Important. Salmon cells in the playlist columns = no playlist covers the topic (see 'Gap / search terms'). Each cell links to the first video listed; the 'Playlist Index' sheet has a link for every video. Header cells link to the playlist.
A3: # | B3: Phase | C3: Topic | D3: What to cover | E3: Priority | F3: Playlists covering (of 5) | G3: A · Engineering Digest Complete Java Programming Course 2026 37 videos | H3: B · Dilip IT Academy JAVA 21 – Free Full Course 102 videos | I3: C · Concept && Coding (Shrayansh) Java from Basics to Advanced 52 videos | J3: D · Coder Army Java Full Course 2026 57 videos | K3: E · Learn Coding Java Programming – 2026 224 videos | L3: Gap / search terms | M3: Status
A4: 1 | B4: 1 · Foundations | C4: Orientation: why Java, roles, roadmap | D4: Why Java, Java developer roles, SDE roadmap, programming vs coding, static vs dynamic typing, Java vs Python | E4: Good to know | F4: =COUNTA(G4:K4) -> 4 | H4: #1 Why Java | Roadmap & Importance of Java (1h 22m 5s) #2 Role of Frontend/Backend/ Full Stack Developer | Lang. v/s Framework (1h 20m 57s) #3 Importance of Micro Services & Java Language Release & Version Details (1h 27m) #4 What is Operating System & Prog. Lang. | Types of Software Application (1h 11m 7s) | I4: #1 Ultimate Java Basics to Advanced Roadmap | Java Course Roadmap for Beginners (4m 42s) | J4: #1 Introduction to JAVA | Java Full Course for Beginners in 2026 (59m 7s) | K4: ▶ 6 videos: #3–7, #131 (~0.7 h) Starts with: SDE Roadmap: Software Developer Roadmap for 2026 | M4: Not started
A5: 2 | B5: 1 · Foundations | C5: Java history, features, editions | D5: History, key features, platform independence, JSE vs JEE vs JME | E5: Important | F5: =COUNTA(G5:K5) -> 3 | H5: #7 Features of Java | Platform Dependent vs InDependent (1h 28m 2s) | J5: #1 Introduction to JAVA | Java Full Course for Beginners in 2026 (59m 7s) #2 Write Your First JAVA Program | JVM, JDK & JRE Explained (41m 34s) | K5: #1 Introduction to Java (Hindi) | What is Java? Explain with Syntax and Example (11m 41s) #9 History of Java Language (Hindi) | जावा का इतिहास क्या है? (5m 26s) #10 Features of Java (Hindi) (6m 59s) | M5: Not started
A6: 3 | B6: 1 · Foundations | C6: Installing JDK & setting up an IDE | D6: JDK install, PATH, IntelliJ / Eclipse / VS Code setup | E6: Good to know | F6: =COUNTA(G6:K6) -> 3 | G6: #1 How to Install Java OpenJDK on Windows 11 (11m 48s) #3 Install IntelliJ IDEA in 5 Minutes! 🚀 Easiest Way for Beginners (2026 Windows Guide) (4m 55s) | H6: #5 Steps of JAVA / JDK Installation | Writing, Execution of Java Program (1h 25m 21s) #20 API Documentation & Eclipse IDE Setup (1h 29m 34s) | K6: #2 How To Setup JAVA For Visual Studio Code | Installation & Code Example (7m 56s) #13 First Java Program | Java Hello World program (4m 41s) | M6: Not started
A7: 4 | B7: 1 · Foundations | C7: JDK vs JRE vs JVM, compile & run flow | D7: javac, bytecode, JVM, JIT, source vs bytecode, compiler vs interpreter | E7: ★ Critical | F7: =COUNTA(G7:K7) -> 5 | G7: #2 What is JDK, JVM, JRE, javac, Byte code, JIT ? Complete Execution Process ! (12m 23s) | H7: #6 Java Compiler v/s Interpreter | What is JVM (1h 28m 24s) | I7: #3 How Java Program Works and its 3 Important Components (JVM, JRE and JDK) with Example (36m 2s) | J7: #2 Write Your First JAVA Program | JVM, JDK & JRE Explained (41m 34s) | K7: #8 JDK JRE and JVM in Java (Hindi) (6m 9s) #11 Java program Compilation and Execution process in Detail (Hindi) (6m 55s) | M7: Not started
A8: 5 | B8: 1 · Foundations | C8: Program structure & main() | D8: Class skeleton, public static void main, comments, one public class per file, ELC/BLC | E8: Important | F8: =COUNTA(G8:K8) -> 5 | G8: #4 Understanding the skeleton of a Java Program (10m 2s) | H8: #8 Implementation of Class | Execution Flow Of Logic From main() Method (1h 27m 17s) | I8: #4 Quiz Question: Why only 1 Public Class in JAVA file (6m 16s) | J8: #2 Write Your First JAVA Program | JVM, JDK & JRE Explained (41m 34s) #18 AutoBoxing, Abstract classes & POJOs | Why only one public class in java file (1h 12m 1s) | K8: #12 Why public static void main(String args[ ]) in Java? full Explanation (9m 32s) #13 First Java Program | Java Hello World program (4m 41s) #14 comments in java | types of comments in java (10m 42s) #132 ELC and BLC in Java | Executable & Non-Executable Class (14m 51s) | M8: Not started
A9: 6 | B9: 1 · Foundations | C9: Primitive data types | D9: byte/short/int/long/float/double/char/boolean, ranges, memory size, default values, reference vs primitive | E9: ★ Critical | F9: =COUNTA(G9:K9) -> 5 | G9: #5 Primitive Data Types in Java in Hindi (57m 9s) | H9: #9 Overview of Object | Variables & Datatypes (1h 25m 7s) #10 Primitive Datatypes | Range of Values & Memory Allocation (1h 26m 19s) #11 Memory of Primitive Datatypes | Categories of Non-Primitive Data Types (1h 28m 34s) | I9: #5 Java Variables - Part1 | Primitive Data Types in Depth (48m 32s) #7 Java Variables - Part2 | Reference/Non-Primitive Data Types in Depth (42m 51s) | J9: #3 Java Variables & Data Types Explained | Identifiers, Literals, Keywords (1h 6m 43s) | K9: #15 Data Types in Java (Hindi) | What is DataType? full Explanation (5m 24s) | M9: Not started
A10: 7 | B10: 1 · Foundations | C10: Binary representation of numbers | D10: Two's complement, IEEE 754, integer overflow, floating-point precision | E10: Important | F10: =COUNTA(G10:K10) -> 2 | I10: #6 How FLOAT and DOUBLE Number Stored in Memory? | IEEE 754 Representation (20m 50s) | J10: #4 How Java Stores Negative & Floating Point Numbers (57m 55s) | M10: Not started
A11: 8 | B11: 1 · Foundations | C11: Variables, scope, naming, keywords | D11: Local/instance/static variables, scope, identifiers, keywords, literals, tokens, naming conventions | E11: Important | F11: =COUNTA(G11:K11) -> 4 | G11: #6 Java Essentials: How to Properly Name Your Variables (8m 10s) | H11: #12 Data Types & Variables in JAVA (1h 52m 23s) #13 Static vs Non-Static Variables (2h 4m 20s) #14 Static V/S Non-Static Variables (1h 24m 31s) #23 Naming Conventions in Java (1h 33m 53s) | J11: #3 Java Variables & Data Types Explained | Identifiers, Literals, Keywords (1h 6m 43s) | K11: ▶ 6 videos: #16–18, #23–25 (~0.9 h) Starts with: Variables in Java (Hindi) | What is variable? full Explanation with types | M11: Not started
A12: 9 | B12: 1 · Foundations | C12: Type casting & type promotion | D12: Implicit (widening), explicit (narrowing), promotion in expressions | E12: Important | F12: =COUNTA(G12:K12) -> 3 | H12: #63 Type Casting | Implicit & Explicit Type Casting (1h 30m 55s) | J12: #5 Java Type Conversions & Type Promotions Explained | Casting in Java (36m 43s) | K12: #20 Type Casting in Java with Example (Hindi) (11m 35s) | M12: Not started
A13: 10 | B13: 1 · Foundations | C13: Operators | D13: Arithmetic, relational, logical, assignment, unary, ternary, precedence, short-circuit | E13: Important | F13: =COUNTA(G13:K13) -> 5 | G13: #7 Become a Math Wiz: Understanding Arithmetic Operators – From Basics to Advanced! (31m 18s) | H13: #24 Types of Operators in Java (1h 31m 53s) #25 Types of Operators In Java (1h 42m 43s) #26 Operators In Java (1h 25m 54s) | I13: #21 Operators in Java | Different Types of Operators in JAVA (57m 6s) | J13: #6 Java Operators | Arithmetic + Unary + Logical + Bitwise + Assignment Operators (2h 8m 10s) | K13: ▶ 7 videos: #26–32 (~0.8 h) Starts with: Operators in Java (Hindi) | What is Operator? Discuss with types | M13: Not started
A14: 11 | B14: 1 · Foundations | C14: Bitwise operators & shifts | D14: &, |, ^, ~, <<, >>, >>> | E14: Important | F14: =COUNTA(G14:K14) -> 3 | G14: #8 Bitwise operators in Java (17m 40s) | J14: #6 Java Operators | Arithmetic + Unary + Logical + Bitwise + Assignment Operators (2h 8m 10s) | K14: #33 Bitwise Operators Example in Java (Hindi) (11m 28s) | M14: Not started
A15: 12 | B15: 1 · Foundations | C15: Console input / output | D15: Scanner, BufferedReader, System.in, print/println/printf, Console class | E15: Important | F15: =COUNTA(G15:K15) -> 4 | G15: #9 Println vs Print vs Printf in Java (20m 49s) | H15: #33 User Dynamic Input of Data In Java (1h 37m 10s) | J15: #20 Java I/O Deep Dive | InputStreams, System.in, Scanner vs BufferedReader (1h 11m 13s) | K15: #21 Input & Output in Java (hindi) (13m 18s) #22 How to take input from user in Java (6m 49s) #130 Console Class in Java with Example | readLine() and readPassword() methods in Java (10m 23s) | M15: Not started
A16: 13 | B16: 1 · Foundations | C16: Conditional statements | D16: if / else-if ladder / nested if, switch | E16: Important | F16: =COUNTA(G16:K16) -> 5 | G16: #12 How to Use Conditional Statements in Java: If, Else If, Else, Switch case (32m 22s) | H16: #27 Control Flow Statements (1h 36m 35s) #28 Control Statements In Java (1h 19m 2s) #29 Switch Statement In Java (1h 41m 33s) | I16: #22 Control Flow Statements in Java | Decision Making, Looping and Branching Statements (52m 9s) | J16: #7 Java Conditional Statements | If, If-Else, If-Else-If Ladder, Switch Explained (1h 21m 29s) | K16: ▶ 6 videos: #34–39 (~1.0 h) Starts with: Decision Making Statements ( if, if else, else if ladder, nested if else, switch) in Java | M16: Not started
A17: 14 | B17: 1 · Foundations | C17: Loops & jump statements | D17: for, for-each, while, do-while, break, continue, labeled break/continue | E17: Important | F17: =COUNTA(G17:K17) -> 5 | G17: #13 Java Loops Explained: For, While, and Do-While Loops (30m 54s) | H17: #30 Looping Statements In Java (1h 41m 3s) #31 Looping Statements In Java (1h 28m 29s) #32 Branching Statements In Java (1h 24m 40s) | I17: #22 Control Flow Statements in Java | Decision Making, Looping and Branching Statements (52m 9s) | J17: #8 Java Loops & Jump Statements | for, while, do-while, break, continue Explained (1h 25m 7s) | K17: ▶ 6 videos: #40–45 (~1.0 h) Starts with: Looping Statements in Java (Hindi) | loops in Java | M17: Not started
A18: 15 | B18: 1 · Foundations | C18: Arrays: 1D, 2D, jagged | D18: Declaration, initialization, memory layout (heap, contiguous), default values, length | E18: Important | F18: =COUNTA(G18:K18) -> 4 | G18: #14 Mastering Java Arrays: 1D, 2D, and Jagged Arrays Explained (34m 41s) | H18: #36 Arrays In Java (1h 37m 37s) #37 Arrays & Array Operations In Java (1h 41m 16s) #38 Arrays & Array Operations In Java (1h 39m 46s) | J18: #9 Introduction to Arrays | Declaration, Initialization, Traversal (1h 47m 1s) #10 How Arrays work in Java | Heap, Contiguous Storage, Random Access (54m 3s) | K18: #91 Arrays in Java (Hindi) | What is array? Explain with Syntax & Example (17m 8s) | M18: Not started
A19: 16 | B19: 1 · Foundations | C19: Array operations & Arrays class | D19: sort, fill, copyOf, binarySearch, equals, deepToString, search/insert/delete | E19: Important | F19: =COUNTA(G19:K19) -> 2 | H19: #37 Arrays & Array Operations In Java (1h 41m 16s) #38 Arrays & Array Operations In Java (1h 39m 46s) | K19: ▶ 16 videos: #92–107 (~2.4 h) Starts with: Print array elements in Java | M19: Not started
A20: 17 | B20: 1 · Foundations | C20: Array covariance & ArrayStoreException | D20: Why Object[] = new String[] compiles, runtime failure | E20: Good to know | F20: =COUNTA(G20:K20) -> 0 | L20: NOT COVERED — Search: java array covariance ArrayStoreException | M20: Not started
A21: 18 | B21: 1 · Foundations | C21: Command-line arguments | D21: String[] args, passing and parsing arguments | E21: Good to know | F21: =COUNTA(G21:K21) -> 2 | H21: #39 Command Line Arguments In Java (1h 28m 55s) | J21: #15 Static & Final in Java | Static Methods, Blocks & String[] args (45m 28s) | M21: Not started
A22: 19 | B22: 1 · Foundations | C22: Methods | D22: Declaration, parameters, return types, overloading, varargs, signature | E22: Important | F22: =COUNTA(G22:K22) -> 5 | G22: #16 Methods in Java (29m 38s) | H22: #15 Methods in Java (1h 27m 2s) #16 Methods in Java (1h 32m 57s) #17 Methods in Java (1h 29m 47s) #18 How to Access Methods in Java (1h 33m 36s) | I22: #8 Java Methods in Depth | Different Types of Methods with Examples (1h 1m 10s) | J22: #11 Java Functions Deep Dive | Recursion (1h 24m 50s) | K22: #121 Methods in Java (Hindi) | What is method? Explain with Syntax & Example (13m 37s) #122 Static vs Non-Static Method in Java (7m 28s) #123 How to use Methods in Java (12m 38s) #172 var arg method in java (13m 7s) | M22: Not started
A23: 20 | B23: 1 · Foundations | C23: Recursion | D23: Base case, call stack, stack depth, recursion vs iteration | E23: Important | F23: =COUNTA(G23:K23) -> 3 | G23: #17 Easiest Way to Learn Recursion: Beginner-Friendly Guide (13m 23s) | J23: #11 Java Functions Deep Dive | Recursion (1h 24m 50s) | K23: #124 Recursion in Java (Hindi) (12m 34s) #125 Java Program to Find Factorial using Recursion (11m 28s) | M23: Not started
A24: 21 | B24: 1 · Foundations | C24: Pass-by-value & object copying basics | D24: Why Java is always pass-by-value (even for references), object size | E24: ★ Critical | F24: =COUNTA(G24:K24) -> 1 | J24: #14 Objects Deep Dive | Size, Call by Value vs Reference (44m 21s) | L24: Partial: only 1 video (D#14). Search: java pass by value vs pass by reference | M24: Not started
A25: 22 | B25: 1 · Foundations | C25: Practice programs: numbers, patterns, series, matrices | D25: Prime, palindrome, Armstrong, factorial, Fibonacci, star/number patterns, matrix programs | E25: Good to know | F25: =COUNTA(G25:K25) -> 1 | K25: ▶ 56 videos: #19, #48–83, #85–90, #108–120 (~8.2 h) Starts with: Add two numbers program in Java (without user input) | M25: Not started
A26: 23 | B26: 1 · Foundations | C26: Strings: immutability & string pool | D26: Heap storage, string pool, intern(), why String is immutable, == vs equals() | E26: ★ Critical | F26: =COUNTA(G26:K26) -> 3 | G26: #10 Java Strings Explained: Understanding String Data Types, Heap Storage, and String Pool (18m 38s) | J26: #25 Java Strings | String Pool, Immutability, Internals (1h 8m 59s) | K26: #126 What is String? full Explanation | Why String is Immutable in Java (19m 12s) | M26: Not started
A27: 24 | B27: 1 · Foundations | C27: String methods | D27: substring, split, replace, compareTo, format, join, strip, repeat | E27: Important | F27: =COUNTA(G27:K27) -> 4 | G27: #11 Master Java String Methods: A Comprehensive Guide for Beginners (26m 8s) | H27: #19 String Methods & Operations in Java (1h 30m 44s) | J27: #26 Java Strings Part 2 | All String Methods + StringBuilder vs StringBuffer (1h 15m 55s) | K27: #127 Java Program to Compare Two Strings (8m 43s) #128 String Methods in Java | toLowerCase(), toUpperCase(), concat(), length(), trim(), replace() etc... (11m 46s) | M27: Not started
A28: 25 | B28: 1 · Foundations | C28: String vs StringBuilder vs StringBuffer | D28: Mutability, thread-safety, performance | E28: Important | F28: =COUNTA(G28:K28) -> 3 | G28: #37 Java String vs StringBuilder vs StringBuffer: Best Practices & Performance (13m 15s) | J28: #26 Java Strings Part 2 | All String Methods + StringBuilder vs StringBuffer (1h 15m 55s) | K28: #129 Java program to reverse a string | StringBuffer and StringBuilder Class in Java (8m 56s) | M28: Not started
A29: 26 | B29: 1 · Foundations | C29: Regular expressions | D29: Pattern, Matcher, groups, quantifiers, lookahead | E29: Good to know | F29: =COUNTA(G29:K29) -> 0 | L29: NOT COVERED — Search: java regex Pattern Matcher tutorial; java regular expressions lookahead groups | M29: Not started
A30: 27 | B30: 2 · OOP | C30: OOP overview: four pillars | D30: Encapsulation, inheritance, polymorphism, abstraction | E30: ★ Critical | F30: =COUNTA(G30:K30) -> 4 | G30: #15 Master OOP in Java: Encapsulation, Abstraction, Polymorphism & Inheritance Explained in 20 Minutes (22m 47s) | I30: #2 OOPs Concept in Java with Examples | 4 Pillars of Object Oriented Programming (OOPs) (1h 36m 42s) | J30: #12 Object Oriented Programming in Java | Classes, Objects, new Keyword (1h 5m 11s) | K30: #133 Java Basic OOP Concepts | Features of OOPs in Java (6m 19s) | M30: Not started
A31: 28 | B31: 2 · OOP | C31: Classes & objects | D31: Class vs object, new keyword, object creation flow, heap/stack | E31: Important | F31: =COUNTA(G31:K31) -> 4 | H31: #7 Features of Java | Platform Dependent vs InDependent (1h 28m 2s) #8 Implementation of Class | Execution Flow Of Logic From main() Method (1h 27m 17s) | I31: #11 Java Classes in Depth - Part1 | Nested Class, Concrete, Abstract, Object, Super and Sub Class (50m 21s) | J31: #12 Object Oriented Programming in Java | Classes, Objects, new Keyword (1h 5m 11s) | K31: #134 Class and Object in Java (9m 41s) #168 new keyword in java (12m 32s) | M31: Not started
A32: 29 | B32: 2 · OOP | C32: Constructors | D32: Default, parameterized, copy, private, overloading, chaining with this() | E32: Important | F32: =COUNTA(G32:K32) -> 5 | G32: #20 What are constructors in Java ? (8m) | H32: #34 Constructors In Java (1h 25m 56s) #35 Constructors & Types of Constructors In Java (1h 29m 48s) | I32: #9 Java Constructor in Depth | Different Types of Constructor with Examples (35m 25s) | J32: #13 Constructors in Java | Constructor Chaining, Overloading & this (58m 2s) | K32: ▶ 6 videos: #135–140 (~0.9 h) Starts with: Constructors in Java | what is constructor? with syntax and example | M32: Not started
A33: 30 | B33: 2 · OOP | C33: Initialization blocks & order | D33: Static block, instance block, initialization order | E33: Important | F33: =COUNTA(G33:K33) -> 1 | K33: #141 instance block in java (8m 47s) #142 static block in java (8m 12s) #143 instance block Vs static block in Java (7m 56s) | L33: Partial: init order across inheritance not covered by title. Search: java initialization order static instance block constructor | M33: Not started
A34: 31 | B34: 2 · OOP | C34: this & super keywords | D34: this vs super, constructor calling order | E34: Important | F34: =COUNTA(G34:K34) -> 3 | H34: #53 this & super keywords | Difference between this & super (1h 37m 34s) #54 this & super keywords | Difference between this & super (1h 36m 16s) #55 this & super keywords | Difference between this & super (1h 24m 25s) | J34: #13 Constructors in Java | Constructor Chaining, Overloading & this (58m 2s) #16 Encapsulation & Inheritance in Java | Java Packages & Super Keyword (1h 38m 2s) | K34: #149 Super Keyword in Java (14m 14s) #150 this keyword in java (14m 15s) | M34: Not started
A35: 32 | B35: 2 · OOP | C35: Encapsulation | D35: Data hiding, getters/setters, immutability link | E35: Important | F35: =COUNTA(G35:K35) -> 4 | G35: #19 Encapsulation in Java in 15 minutes (16m 49s) | H35: #59 Encapsulation in Java | Data Binding in Java (1h 27m 15s) | J35: #16 Encapsulation & Inheritance in Java | Java Packages & Super Keyword (1h 38m 2s) | K35: #154 Encapsulation in Java (10m 46s) | M35: Not started
A36: 33 | B36: 2 · OOP | C36: Access modifiers | D36: public, protected, default, private | E36: Important | F36: =COUNTA(G36:K36) -> 2 | G36: #24 Access Modifiers: Public, Private, Default & Protected (25m 11s) | H36: #58 Access Specifiers | Access Modifiers (50m) | M36: Not started
A37: 34 | B37: 2 · OOP | C37: Inheritance | D37: Types of inheritance, extends, why no multiple inheritance, super, constructor order | E37: ★ Critical | F37: =COUNTA(G37:K37) -> 4 | G37: #21 Inheritance in Java (34m 36s) | H37: #41 Inheritence & Types of Inheritence In Java (1h 28m 5s) #42 Inheritence & Types of Inheritence In Java (1h 20m 10s) #43 Implementation of Inheritence With Examples (1h 36m 2s) | J37: #16 Encapsulation & Inheritance in Java | Java Packages & Super Keyword (1h 38m 2s) | K37: ▶ 5 videos: #144–148 (~0.7 h) Starts with: Inheritance in Java (hindi) | What is Inheritance? full Explanation | M37: Not started
A38: 35 | B38: 2 · OOP | C38: Overloading vs overriding | D38: Overriding rules, covariant return type, @Override, real-time examples | E38: ★ Critical | F38: =COUNTA(G38:K38) -> 4 | G38: #16 Methods in Java (29m 38s) #22 Polymorphism: Compile Time vs Run Time ( Dynamic Method Dispatch ) (14m 45s) | H38: #50 Method Overloading & Method Overriding | Polymorphism (1h 29m 38s) #51 Method Overriding | Real Time Examples of Method Overriding (1h 31m 11s) | J38: #11 Java Functions Deep Dive | Recursion (1h 24m 50s) | K38: #152 Method Overloading in Java (9m 59s) #153 Method Overriding in Java (11m 16s) #170 @override annotation in java (10m 4s) #171 covariant return type in java (10m 43s) | M38: Not started
A39: 36 | B39: 2 · OOP | C39: Polymorphism | D39: Compile-time vs runtime, dynamic method dispatch | E39: ★ Critical | F39: =COUNTA(G39:K39) -> 4 | G39: #22 Polymorphism: Compile Time vs Run Time ( Dynamic Method Dispatch ) (14m 45s) | H39: #56 polymorphism | compiletime/static & runtime/dynamic polymorphism (1h 32m 30s) #57 polymorphism | compiletime/static & runtime/dynamic polymorphism (1h 8m 9s) | J39: #17 Abstraction & Polymorphism in Depth | Abstract Class vs Interfaces (1h 28m 1s) | K39: #151 Polymorphism in Java (4m 7s) | M39: Not started
A40: 37 | B40: 2 · OOP | C40: Upcasting, downcasting, instanceof | D40: Reference casting, ClassCastException, instanceof pattern | E40: Important | F40: =COUNTA(G40:K40) -> 0 | L40: NOT COVERED — Search: java upcasting downcasting instanceof ClassCastException | M40: Not started
...

Sheet Summary
A1: Summary
A3: Playlists
A4: Key | B4: Playlist | C4: Channel | D4: Videos | E4: Total hours | F4: Roadmap topics covered | G4: % of roadmap covered
A5: A | B5: Complete Java Programming Course 2026 | C5: Engineering Digest | D5: =COUNTIF('Playlist Index'!$A$2:$A$473,A5) -> 37 | E5: =SUMIF('Playlist Index'!$A$2:$A$473,A5,'Playlist Index'!$F$2:$F$473)/60 -> 25.015 | F5: =COUNTA(Roadmap!G4:G144) -> 53 | G5: =F5/COUNTA(Roadmap!$C$4:$C$144) -> 0.37588652
A6: B | B6: JAVA 21 – Free Full Course | C6: Dilip IT Academy | D6: =COUNTIF('Playlist Index'!$A$2:$A$473,A6) -> 102 | E6: =SUMIF('Playlist Index'!$A$2:$A$473,A6,'Playlist Index'!$F$2:$F$473)/60 -> 149.46833 | F6: =COUNTA(Roadmap!H4:H144) -> 58 | G6: =F6/COUNTA(Roadmap!$C$4:$C$144) -> 0.41134752
A7: C | B7: Java from Basics to Advanced | C7: Concept && Coding (Shrayansh) | D7: =COUNTIF('Playlist Index'!$A$2:$A$473,A7) -> 52 | E7: =SUMIF('Playlist Index'!$A$2:$A$473,A7,'Playlist Index'!$F$2:$F$473)/60 -> 38.121667 | F7: =COUNTA(Roadmap!I4:I144) -> 58 | G7: =F7/COUNTA(Roadmap!$C$4:$C$144) -> 0.41134752
A8: D | B8: Java Full Course 2026 | C8: Coder Army | D8: =COUNTIF('Playlist Index'!$A$2:$A$473,A8) -> 57 | E8: =SUMIF('Playlist Index'!$A$2:$A$473,A8,'Playlist Index'!$F$2:$F$473)/60 -> 62.775 | F8: =COUNTA(Roadmap!J4:J144) -> 83 | G8: =F8/COUNTA(Roadmap!$C$4:$C$144) -> 0.58865248
A9: E | B9: Java Programming – 2026 | C9: Learn Coding | D9: =COUNTIF('Playlist Index'!$A$2:$A$473,A9) -> 224 | E9: =SUMIF('Playlist Index'!$A$2:$A$473,A9,'Playlist Index'!$F$2:$F$473)/60 -> 37.648333 | F9: =COUNTA(Roadmap!K4:K144) -> 50 | G9: =F9/COUNTA(Roadmap!$C$4:$C$144) -> 0.35460993
A10: All | D10: =SUM(D5:D9) -> 472 | E10: =SUM(E5:E9) -> 313.02833 | F10: =COUNTA(Roadmap!$C$4:$C$144) -> 141
F11: ↑ total roadmap topics
A13: Your progress
B14: Metric | D14: Count | E14: % of topics
B15: Not started | D15: =COUNTIF(Roadmap!$M$4:$M$144,"Not started") -> 141 | E15: =D15/$F$10 -> 1
B16: In progress | D16: =COUNTIF(Roadmap!$M$4:$M$144,"In progress") -> 0 | E16: =D16/$F$10 -> 0
B17: Done | D17: =COUNTIF(Roadmap!$M$4:$M$144,"Done") -> 0 | E17: =D17/$F$10 -> 0
B18: ★ Critical topics done | D18: =COUNTIFS(Roadmap!$E$4:$E$144,"★ Critical",Roadmap!$M$4:$M$144,"Done") -> 0 | E18: =D18/D19 -> 0
B19: ★ Critical topics total | D19: =COUNTIF(Roadmap!$E$4:$E$144,"★ Critical") -> 36
A21: Gaps
B22: Metric | D22: Count
B23: Topics covered by none of the 5 playlists | D23: =COUNTIF(Roadmap!$F$4:$F$144,0) -> 33
B24: …of which ★ Critical | D24: =COUNTIFS(Roadmap!$F$4:$F$144,0,Roadmap!$E$4:$E$144,"★ Critical") -> 2
B25: Topics covered by only 1 playlist | D25: =COUNTIF(Roadmap!$F$4:$F$144,1) -> 26
B26: Topics covered by 3+ playlists | D26: =COUNTIF(Roadmap!$F$4:$F$144,">=3") -> 62
A28: Notes
A29: • Videos were mapped to topics by title only. Long masterclass videos (A#33 ≈ 3h55m multithreading, A#36 ≈ 7h49m collections + streams) are listed under every topic their title names, so check their chapters.
A30: • A video can appear under several topics. Counts of 'topics covered' therefore overlap with video counts.
A31: • Change a topic's Status on the Roadmap sheet (dropdown) and this sheet updates.

Sheet Playlist Index
A1: Key | B1: Playlist | C1: # | D1: Video (click to open) | E1: Duration | F1: Minutes | G1: Roadmap # | H1: Mapped to topic(s)
A2: A | B2: A · Engineering Digest | C2: 1 | D2: How to Install Java OpenJDK on Windows 11 | E2: 11m 48s | F2: 11.8 | G2: 3 | H2: Installing JDK & setting up an IDE
A3: A | B3: A · Engineering Digest | C3: 2 | D3: What is JDK, JVM, JRE, javac, Byte code, JIT ? Complete Execution Process ! | E3: 12m 23s | F3: 12.4 | G3: 4, 119, 120 | H3: JDK vs JRE vs JVM, compile & run flow; JIT & execution; Bytecode & class files
A4: A | B4: A · Engineering Digest | C4: 3 | D4: Install IntelliJ IDEA in 5 Minutes! 🚀 Easiest Way for Beginners (2026 Windows Guide) | E4: 4m 55s | F4: 4.9 | G4: 3 | H4: Installing JDK & setting up an IDE
A5: A | B5: A · Engineering Digest | C5: 4 | D5: Understanding the skeleton of a Java Program | What is main method in Java ? | E5: 10m 2s | F5: 10 | G5: 5 | H5: Program structure & main()
A6: A | B6: A · Engineering Digest | C6: 5 | D6: Primitive Data Types in Java in Hindi | Byte, Short, Int, Long, Float, Double, Char & Boolean | E6: 57m 9s | F6: 57.1 | G6: 6 | H6: Primitive data types
A7: A | B7: A · Engineering Digest | C7: 6 | D7: Java Essentials: How to Properly Name Your Variables | E7: 8m 10s | F7: 8.2 | G7: 8 | H7: Variables, scope, naming, keywords
A8: A | B8: A · Engineering Digest | C8: 7 | D8: Become a Math Wiz: Understanding Arithmetic Operators – From Basics to Advanced! | E8: 31m 18s | F8: 31.3 | G8: 10 | H8: Operators
A9: A | B9: A · Engineering Digest | C9: 8 | D9: Bitwise operators in Java | and, or, not, xor, left shift, right shift & unsigned right shift | E9: 17m 40s | F9: 17.7 | G9: 11 | H9: Bitwise operators & shifts
A10: A | B10: A · Engineering Digest | C10: 9 | D10: Println vs Print vs Printf in Java | E10: 20m 49s | F10: 20.8 | G10: 12 | H10: Console input / output
A11: A | B11: A · Engineering Digest | C11: 10 | D11: Java Strings Explained: Understanding String Data Types, Heap Storage, and String Pool | E11: 18m 38s | F11: 18.6 | G11: 23 | H11: Strings: immutability & string pool
A12: A | B12: A · Engineering Digest | C12: 11 | D12: Master Java String Methods: A Comprehensive Guide for Beginners | E12: 26m 8s | F12: 26.1 | G12: 24 | H12: String methods
A13: A | B13: A · Engineering Digest | C13: 12 | D13: How to Use Conditional Statements in Java: If, Else If, Else, Switch case | E13: 32m 22s | F13: 32.4 | G13: 13 | H13: Conditional statements
... A473: E | B473: E · Learn Coding | C473: 224 | D473: Java Interview Questions & Answers | Learn Coding | E473: 16m 50s | F473: 16.8 | G473: 141 | H473: Interview MCQs & Q&A

Sheet Gaps - To Search
A1: Topics the 5 playlists don't cover (or only touch in a title)
A2: Static list generated from the Roadmap sheet. Sorted by priority. 'Partial' = mentioned in a video title but not a dedicated lesson.
A4: Roadmap # | B4: Phase | C4: Topic | D4: Priority | E4: Type | F4: What to cover | G4: Search terms / note
A5: 75 | B5: 5 · Collections | C5: Time complexity & choosing a collection | D5: ★ Critical | E5: Not covered | F5: Big-O of each structure, decision guide | G5: Search: java collections time complexity cheat sheet
A6: 102 | B6: 8 · Concurrency | C6: Concurrent collections | D6: ★ Critical | E6: Not covered | F6: ConcurrentHashMap internals, CopyOnWriteArrayList, BlockingQueue family | G6: Search: ConcurrentHashMap internal working java; BlockingQueue producer consumer java
A7: 21 | B7: 1 · Foundations | C7: Pass-by-value & object copying basics | D7: ★ Critical | E7: Partial | F7: Why Java is always pass-by-value (even for references), object size | G7: Only 1 video (D#14). Search: java pass by value vs pass by reference
A8: 97 | B8: 8 · Concurrency | C8: Deadlock, livelock, starvation | D8: ★ Critical | E8: Partial | F8: Causes, detection, prevention | G8: Only named in A#33 (a ~4h video). Search: java deadlock livelock starvation examples prevention
A9: 37 | B9: 2 · OOP | C9: Upcasting, downcasting, instanceof | D9: Important | E9: Not covered | F9: Reference casting, ClassCastException, instanceof pattern | G9: Search: java upcasting downcasting instanceof ClassCastException
A10: 61 | B10: 3 · Exceptions | C10: Exception pitfalls & errors | D10: Important | E10: Not covered | F10: finally with return, swallowing exceptions, overriding + throws rules, StackOverflowError, OutOfMemoryError, assertions | G10: Search: java exception handling best practices pitfalls; java assert keyword; StackOverflowError vs OutOfMemoryError
A11: 64 | B11: 4 · Generics | C11: Type erasure & generics limits | D11: Important | E11: Not covered | F11: Type erasure, bridge methods, raw types, no new T(), no generic arrays | G11: Search: java generics type erasure bridge methods raw types
A12: 74 | B12: 5 · Collections | C12: Immutable collections & pitfalls | D12: Important | E12: Not covered | F12: List.of(), Arrays.asList() pitfalls, unmodifiable vs immutable | G12: Search: List.of vs Arrays.asList vs Collections.unmodifiableList
A13: 86 | B13: 7 · I/O & APIs | C13: Serialization | D13: Important | E13: Not covered | F13: Serializable, serialVersionUID, transient, Externalizable, security concerns | G13: Search: java serialization serialVersionUID transient Externalizable
A14: 88 | B14: 7 · I/O & APIs | C14: Date & Time API | D14: Important | E14: Not covered | F14: LocalDate/Time, ZonedDateTime, Instant, Duration, Period, DateTimeFormatter, DST pitfalls | G14: Search: java 8 date time API LocalDate ZonedDateTime tutorial
A15: 89 | B15: 7 · I/O & APIs | C15: BigInteger & BigDecimal | D15: Important | E15: Not covered | F15: Arbitrary precision, rounding modes, money pitfalls | G15: Search: java BigDecimal BigInteger rounding modes
A16: 114 | B16: 9 · Reflection & Annotations | C16: Class loaders | D16: Important | E16: Not covered | F16: Bootstrap/platform/application loaders, delegation model, custom loader | G16: Search: java classloader delegation model bootstrap platform application
... A48: 135 | B48: 12 · Tooling & Testing | C48: Javadoc & API docs | D48: Good to know | E48: Partial | F48: Reading the JDK API docs, writing Javadoc | G48: B#20 covers reading API docs; writing Javadoc not covered
